Workbook

Sheet Feuille 1
A1: POST NUMBER | B1: POST DATASET ID | C1: POST | D1: Target Group | E1: Target Group (Id. by Grok) | F1: Target Group (Id by Claude) | G1: Human #1 | H1: Human #2 | I1: Grok | J1: Claude AI | K1: Human Annotator #1 | L1: Human Annotator #2 | M1: Platform of Origin | N1: Study Annotator #1 Classification | O1: Study Annotator #1 Target Group | P1: Study Annotator #2 Classification | Q1: Study Annotator #2 Target Group | R1: Study Annotator #3 Classification | S1: Study Annotator #3 Target Group | T1: "Normal" Class. Count | U1: "Offensive" Class. Count | V1: "Hate Speech" Class. Count | W1: Completeness Score | X1: Majority? | Y1: Standard Deviation
A2: 001 | B2: 21376810_gab | C2: exactly if a low iq nigger from africa who can not read can understand islam i think i can understand kill the kuffar nothing subtle lost on me | D2: African, Muslim | E2: AfricanBlack, Muslim | F2: Black people, Muslims | G2: Offensive | H2: Offensive | I2: Hate Speech | J2: Hate Speech | K2: GM#5 | L2: GM#4 | M2: Gab | N2: hatespeech | O2: African | P2: hatespeech | Q2: African, Buddhism | R2: hatespeech | S2: African | T2: =COUNTIF(G2:J2,"*Normal*") -> 0 | U2: =COUNTIF(G2:J2,"*Offensive*") -> 2 | V2: =COUNTIF(G2:J2,"*Hate Speech*") -> 2 | W2: =SUM(T2:V2)/4 -> 1 | X2: =IF(T2>2,"Normal", IF(U2>2, "Offensive", IF(V2>2, "Hate Speech"))) -> FALSE | Y2: =STDEV(T2:V2) -> 1.1547005
A3: 002 | B3: 1080843707643944965_twitter | C3: <user> yes because it is and i sound so broken bitch when did i have feelings | D3: None | E3: Women | F3: N/A | G3: Normal | H3: Normal | I3: Offensive | J3: Normal | K3: GM#5 | L3: GM#3 | M3: Twitter | N3: normal | O3: None | P3: offensive | Q3: None | R3: normal | S3: Women | T3: =COUNTIF(G3:J3,"*Normal*") -> 3 | U3: =COUNTIF(G3:J3,"*Offensive*") -> 1 | V3: =COUNTIF(G3:J3,"*Hate Speech*") -> 0 | W3: =SUM(T3:V3)/4 -> 1 | X3: =IF(T3>2,"Normal", IF(U3>2, "Offensive", IF(V3>2, "Hate Speech"))) -> Normal | Y3: =STDEV(T3:V3) -> 1.5275252
A4: 003 | B4: 1178183797461811200_twitter | C4: a white man tired to slide the phase i was the nigger when describing his up bringing in japan tonight at dinner white privilege continues to be heavy people have such low level of compassion no one is hiding their racism anymore | D4: African | E4: AfricanBlack | F4: Black people | G4: Normal | H4: Normal | I4: Hate Speech | J4: Hate Speech | K4: GM#5 | L4: GM#1 | M4: Twitter | N4: normal | O4: None | P4: normal | Q4: None | R4: normal | S4: None | T4: =COUNTIF(G4:J4,"*Normal*") -> 2 | U4: =COUNTIF(G4:J4,"*Offensive*") -> 0 | V4: =COUNTIF(G4:J4,"*Hate Speech*") -> 2 | W4: =SUM(T4:V4)/4 -> 1 | X4: =IF(T4>2,"Normal", IF(U4>2, "Offensive", IF(V4>2, "Hate Speech"))) -> FALSE | Y4: =STDEV(T4:V4) -> 1.1547005
A5: 004 | B5: 1178917247626203136_twitter | C5: <user> <user> <user> <user> <user> trump said he loves the educated he loves the uneducated he loves men he loves women he loves legal immigrants he loves americans people with severe tds omg trump said he prefers dumb white uneducated men | D5: Education, Woman, Immigrant, Americans, | E5: White People | F5: N/A | G5: Normal | H5: Offensive | I5: Normal | J5: Normal | K5: GM#5 | L5: GM#2 | M5: Twitter | N5: normal | O5: None | P5: normal | Q5: None | R5: offensive | S5: Caucasian | T5: =COUNTIF(G5:J5,"*Normal*") -> 3 | U5: =COUNTIF(G5:J5,"*Offensive*") -> 1 | V5: =COUNTIF(G5:J5,"*Hate Speech*") -> 0 | W5: =SUM(T5:V5)/4 -> 1 | X5: =IF(T5>2,"Normal", IF(U5>2, "Offensive", IF(V5>2, "Hate Speech"))) -> Normal | Y5: =STDEV(T5:V5) -> 1.5275252
A6: 005 | B6: 19332653_gab | C6: rotherham is the trigger for the world whites allowing the rape of white children by paki muslims and covered up for diversity means many mps councillors police should be swinging from a rope and any fucked up media rep who refuses to see the truth | D6: Muslim | E6: Muslim, Asian (Pakistani) | F6: Muslims, Politicians | G6: Hate Speech | H6: Offensive | I6: Hate Speech | J6: Hate Speech | K6: GM#5 | L6: GM#4 | M6: Gab | N6: normal | O6: None | P6: normal | Q6: None | R6: normal | S6: None | T6: =COUNTIF(G6:J6,"*Normal*") -> 0 | U6: =COUNTIF(G6:J6,"*Offensive*") -> 1 | V6: =COUNTIF(G6:J6,"*Hate Speech*") -> 3 | W6: =SUM(T6:V6)/4 -> 1 | X6: =IF(T6>2,"Normal", IF(U6>2, "Offensive", IF(V6>2, "Hate Speech"))) -> Hate Speech | Y6: =STDEV(T6:V6) -> 1.5275252
A7: 006 | B7: 9841810_gab | C7: jews couch their distrust of whites as if it were a logical response to random violence that we routinely heap upon them because of our barbaric gentile ways the truth though is that they want us gone because we are the only ones who routinely oppose their nefarious schemes for domination | D7: Jewish | E7: Jewish people | F7: Jewish people | G7: Offensive | H7: Offensive | I7: Hate Speech | J7: Hate Speech | K7: GM#5 | L7: GM#3 | M7: Gab | N7: offensive | O7: Jewish | P7: normal | Q7: Jewish | R7: normal | S7: None | T7: =COUNTIF(G7:J7,"*Normal*") -> 0 | U7: =COUNTIF(G7:J7,"*Offensive*") -> 2 | V7: =COUNTIF(G7:J7,"*Hate Speech*") -> 2 | W7: =SUM(T7:V7)/4 -> 1 | X7: =IF(T7>2,"Normal", IF(U7>2, "Offensive", IF(V7>2, "Hate Speech"))) -> FALSE | Y7: =STDEV(T7:V7) -> 1.1547005
A8: 007 | B8: 1218921638139326467_twitter | C8: i need my back cracked like a mf glow stick by them tiny little asians in la | D8: Asian | E8: ChineseAsian | F8: N/A | G8: Offensive | H8: Normal | I8: Offensive | J8: Normal | K8: GM#5 | L8: GM#1 | M8: Twitter | N8: offensive | O8: Asian | P8: normal | Q8: Asian | R8: offensive | S8: Asian, Women | T8: =COUNTIF(G8:J8,"*Normal*") -> 2 | U8: =COUNTIF(G8:J8,"*Offensive*") -> 2 | V8: =COUNTIF(G8:J8,"*Hate Speech*") -> 0 | W8: =SUM(T8:V8)/4 -> 1 | X8: =IF(T8>2,"Normal", IF(U8>2, "Offensive", IF(V8>2, "Hate Speech"))) -> FALSE | Y8: =STDEV(T8:V8) -> 1.1547005
A9: 008 | B9: 1087224984639033344_twitter | C9: <user> if u were askin her out would she not realize ur not gay | D9: Homosexual | E9: LGBTQ+ | F9: N/A | G9: Offensive | H9: Normal | I9: Offensive | J9: Normal | K9: GM#5 | L9: GM#2 | M9: Twitter | N9: normal | O9: Homosexual | P9: normal | Q9: Homosexual | R9: normal | S9: Homosexual | T9: =COUNTIF(G9:J9,"*Normal*") -> 2 | U9: =COUNTIF(G9:J9,"*Offensive*") -> 2 | V9: =COUNTIF(G9:J9,"*Hate Speech*") -> 0 | W9: =SUM(T9:V9)/4 -> 1 | X9: =IF(T9>2,"Normal", IF(U9>2, "Offensive", IF(V9>2, "Hate Speech"))) -> FALSE | Y9: =STDEV(T9:V9) -> 1.1547005
A10: 009 | B10: 1178639561502707713_twitter | C10: this happens a lot in the makeup beauty community gay men think that the women who have a problem with drag queens or with gay men using misogynistic slurs etc all must be str8 girls who do not know how the lgbt community works guess what dykes hate you too | D10: Homosexual | E10: Homosexual, Queer | F10: Gay men, Women | G10: Offensive | H10: Offensive | I10: Offensive | J10: Offensive | K10: GM#5 | L10: GM#4 | M10: Twitter | N10: normal | O10: None | P10: normal | Q10: None | R10: normal | S10: None | T10: =COUNTIF(G10:J10,"*Normal*") -> 0 | U10: =COUNTIF(G10:J10,"*Offensive*") -> 4 | V10: =COUNTIF(G10:J10,"*Hate Speech*") -> 0 | W10: =SUM(T10:V10)/4 -> 1 | X10: =IF(T10>2,"Normal", IF(U10>2, "Offensive", IF(V10>2, "Hate Speech"))) -> Offensive | Y10: =STDEV(T10:V10) -> 2.3094011
A11: 010 | B11: 20156398_gab | C11: of course there will always be white actors and actresses it just they are slated to always play villains and nigger whores western pop culture is devolving into niggerdom at such frightening pace it truly is painful to watch | D11: African, Woman | E11: Black people | F11: Black people | G11: Offensive | H11: Offensive | I11: Hate Speech | J11: Hate Speech | K11: GM#5 | L11: GM#3 | M11: Gab | N11: hatespeech | O11: Women, African | P11: hatespeech | Q11: African, Women | R11: hatespeech | S11: African | T11: =COUNTIF(G11:J11,"*Normal*") -> 0 | U11: =COUNTIF(G11:J11,"*Offensive*") -> 2 | V11: =COUNTIF(G11:J11,"*Hate Speech*") -> 2 | W11: =SUM(T11:V11)/4 -> 1 | X11: =IF(T11>2,"Normal", IF(U11>2, "Offensive", IF(V11>2, "Hate Speech"))) -> FALSE | Y11: =STDEV(T11:V11) -> 1.1547005
A12: 011 | B12: 1080898632050724864_twitter | C12: gt raped by light <user> <user> | D12: None | E12: Victims of SA | F12: Women | G12: Offensive | H12: Offensive | I12: Offensive | J12: Offensive | K12: GM#5 | L12: GM#1 | M12: Twitter | N12: offensive | O12: None | P12: normal | Q12: None | R12: offensive | S12: None | T12: =COUNTIF(G12:J12,"*Normal*") -> 0 | U12: =COUNTIF(G12:J12,"*Offensive*") -> 4 | V12: =COUNTIF(G12:J12,"*Hate Speech*") -> 0 | W12: =SUM(T12:V12)/4 -> 1 | X12: =IF(T12>2,"Normal", IF(U12>2, "Offensive", IF(V12>2, "Hate Speech"))) -> Offensive | Y12: =STDEV(T12:V12) -> 2.3094011
A13: 012 | B13: 2644271_gab | C13: fakenews that would be the mainstream media cnn msm msnbc cbs nbc etc so please stop blaming us the voter and the alternative media for your stupidity and you going full retard | D13: Journalists, Liberal | E13: Liberals / Media | F13: N/A | G13: Offensive | H13: Offensive | I13: Offensive | J13: Normal | K13: GM#5 | L13: GM#2 | M13: Gab | N13: normal | O13: None | P13: offensive | Q13: Other | R13: offensive | S13: None | T13: =COUNTIF(G13:J13,"*Normal*") -> 1 | U13: =COUNTIF(G13:J13,"*Offensive*") -> 3 | V13: =COUNTIF(G13:J13,"*Hate Speech*") -> 0 | W13: =SUM(T13:V13)/4 -> 1 | X13: =IF(T13>2,"Normal", IF(U13>2, "Offensive", IF(V13>2, "Hate Speech"))) -> Offensive | Y13: =STDEV(T13:V13) -> 1.5275252
A14: 013 | B14: 1181320554227359745_twitter | C14: <user> whoever picked mineecraft is fuckign retarded | D14: None | E14: Disability | F14: People with disabilities | G14: Offensive | I14: Offensive | J14: Offensive | K14: GM#5 | L14: GM#4 | M14: Twitter | N14: offensive | O14: Other | P14: offensive | Q14: None | R14: offensive | S14: None | T14: =COUNTIF(G14:J14,"*Normal*") -> 0 | U14: =COUNTIF(G14:J14,"*Offensive*") -> 3 | V14: =COUNTIF(G14:J14,"*Hate Speech*") -> 0 | W14: =SUM(T14:V14)/4 -> 0.75 | X14: =IF(T14>2,"Normal", IF(U14>2, "Offensive", IF(V14>2, "Hate Speech"))) -> Offensive | Y14: =STDEV(T14:V14) -> 1.7320508
A15: 014 | B15: 12856688_gab | C15: two terror attacks on anglo american cities in one night when is enough enough tolerance is the virtue of a dying society trump better come down hard a moslem ban is a good start but we need an exit strategy we need to deport all moslems now lasvegas canadaterrorattack edmonton | D15: Muslim | E15: Muslim people | F15: N/A | G15: Hate Speech | H15: Offensive | I15: Hate Speech | J15: Normal | K15: GM#5 | L15: GM#3 | M15: Gab | N15: hatespeech | O15: Islam | P15: hatespeech | Q15: Arab, Islam | R15: offensive | S15: Islam | T15: =COUNTIF(G15:J15,"*Normal*") -> 1 | U15: =COUNTIF(G15:J15,"*Offensive*") -> 1 | V15: =COUNTIF(G15:J15,"*Hate Speech*") -> 2 | W15: =SUM(T15:V15)/4 -> 1 | X15: =IF(T15>2,"Normal", IF(U15>2, "Offensive", IF(V15>2, "Hate Speech"))) -> FALSE | Y15: =STDEV(T15:V15) -> 0.57735027
A16: 015 | B16: 13279118_gab | C16: weak milquetoast faggots like you will never change america you are just another civic nationalist cuckold pussy too scared to even talk about race because you are such a chickenshit so scared like a woman of being called a wayciss or a white supwemasiss lol what a nutless coward | D16: Homosexual | E16: Homosexual, Caucasian | F16: Gay people | G16: Offensive | I16: Hate Speech | J16: Offensive | K16: GM#5 | L16: GM#1 | M16: Gab | N16: hatespeech | O16: Homosexual, Women | P16: hatespeech | Q16: Homosexual, Caucasian, Women | R16: offensive | S16: Homosexual, Women | T16: =COUNTIF(G16:J16,"*Normal*") -> 0 | U16: =COUNTIF(G16:J16,"*Offensive*") -> 2 | V16: =COUNTIF(G16:J16,"*Hate Speech*") -> 1 | W16: =SUM(T16:V16)/4 -> 0.75 | X16: =IF(T16>2,"Normal", IF(U16>2, "Offensive", IF(V16>2, "Hate Speech"))) -> FALSE | Y16: =STDEV(T16:V16) -> 1
A17: 016 | B17: 4464004_gab | C17: journalists are showing themselves to be the retarded liberals they are the tradition of ap can die the traditional press corps can die in gas station bathrooms | D17: Journalists, Liberal | E17: Liberals / Media | F17: People with disabilities, Liberals | G17: Offensive | H17: Hate Speech | I17: Offensive | J17: Offensive | K17: GM#5 | L17: GM#2 | M17: Gab | N17: hatespeech | O17: Other | P17: offensive | Q17: Other | R17: offensive | S17: None | T17: =COUNTIF(G17:J17,"*Normal*") -> 0 | U17: =COUNTIF(G17:J17,"*Offensive*") -> 3 | V17: =COUNTIF(G17:J17,"*Hate Speech*") -> 1 | W17: =SUM(T17:V17)/4 -> 1 | X17: =IF(T17>2,"Normal", IF(U17>2, "Offensive", IF(V17>2, "Hate Speech"))) -> Offensive | Y17: =STDEV(T17:V17) -> 1.5275252
A18: 017 | B18: 1178643287873335296_twitter | C18: feel phylliscitations to daff mr hairwigger who has just hadded twinned little curls he was resting between horrockses sheets wailing for white warfare prooboor welsht breton | E18: AfricanBlack, Caucasian | F18: N/A | I18: Hate Speech | J18: Normal | K18: GM#5 | L18: GM#4 | M18: Twitter | N18: normal | O18: None | P18: normal | Q18: None | R18: normal | S18: None | T18: =COUNTIF(G18:J18,"*Normal*") -> 1 | U18: =COUNTIF(G18:J18,"*Offensive*") -> 0 | V18: =COUNTIF(G18:J18,"*Hate Speech*") -> 1 | W18: =SUM(T18:V18)/4 -> 0.5 | X18: =IF(T18>2,"Normal", IF(U18>2, "Offensive", IF(V18>2, "Hate Speech"))) -> FALSE | Y18: =STDEV(T18:V18) -> 0.57735027
A19: 018 | B19: 4496379_gab | C19: detention space for illegal immigrants oh my dare i say concentration camps gas the spics border war now in all seriousness detention camps are necessary you can not let beaners roam around raping and pillaging you have to lock up all the taco niggers until you are ready to remove them | D19: Immigrant, African | E19: Hispanic people, Black people | F19: Hispanic people | G19: Hate Speech | H19: Hate Speech | I19: Hate Speech | J19: Hate Speech | K19: GM#5 | L19: GM#3 | M19: Gab | N19: offensive | O19: Hispanic | P19: hatespeech | Q19: Hispanic | R19: hatespeech | S19: Refugee, Hispanic | T19: =COUNTIF(G19:J19,"*Normal*") -> 0 | U19: =COUNTIF(G19:J19,"*Offensive*") -> 0 | V19: =COUNTIF(G19:J19,"*Hate Speech*") -> 4 | W19: =SUM(T19:V19)/4 -> 1 | X19: =IF(T19>2,"Normal", IF(U19>2, "Offensive", IF(V19>2, "Hate Speech"))) -> Hate Speech | Y19: =STDEV(T19:V19) -> 2.3094011
A20: 019 | B20: 1086417563444232194_twitter | C20: <user> let be honest multiculturalism is just a euphemism for hostile takeover by jews and non whites | D20: Jewish | E20: Jewish | F20: Jewish people | G20: Offensive | H20: Offensive | I20: Hate Speech | J20: Hate Speech | K20: GM#5 | L20: GM#1 | M20: Twitter | N20: offensive | O20: African, Arab, Asian, Hispanic, Jewish | P20: hatespeech | Q20: Jewish | R20: hatespeech | S20: Other | T20: =COUNTIF(G20:J20,"*Normal*") -> 0 | U20: =COUNTIF(G20:J20,"*Offensive*") -> 2 | V20: =COUNTIF(G20:J20,"*Hate Speech*") -> 2 | W20: =SUM(T20:V20)/4 -> 1 | X20: =IF(T20>2,"Normal", IF(U20>2, "Offensive", IF(V20>2, "Hate Speech"))) -> FALSE | Y20: =STDEV(T20:V20) -> 1.1547005
A21: 020 | B21: 23292228_gab | C21: basically if the democrats want something it because they figure that in the long run it makes it easier for gay latino muslims to rape your kids mpcstatusupdates | D21: Democrat, Latino, Muslim | E21: Muslim, Latino, LGBTQ+ | F21: N/A | G21: Offensive | H21: Offensive | I21: Hate Speech | J21: Normal | K21: GM#5 | L21: GM#2 | M21: Gab | N21: hatespeech | O21: Hispanic, Islam | P21: hatespeech | Q21: Homosexual, Arab, Hispanic, Islam, Men, Women | R21: offensive | S21: Arab, Hispanic, Islam | T21: =COUNTIF(G21:J21,"*Normal*") -> 1 | U21: =COUNTIF(G21:J21,"*Offensive*") -> 2 | V21: =COUNTIF(G21:J21,"*Hate Speech*") -> 1 | W21: =SUM(T21:V21)/4 -> 1 | X21: =IF(T21>2,"Normal", IF(U21>2, "Offensive", IF(V21>2, "Hate Speech"))) -> FALSE | Y21: =STDEV(T21:V21) -> 0.57735027
A22: 021 | B22: 21333143_gab | C22: are they 2 nd 3 rd 4 th wives the muslim child birth rate is out of control and the <number> bastard are letting it carry on they really believe that soft politics will curb their desire to have a calliohate in the uk <number> mps and so delusional and dangerous | D22: Muslim | E22: Muslim | F22: Muslims | G22: Offensive | H22: Offensive | I22: Hate Speech | J22: Hate Speech | K22: GM#5 | L22: GM#4 | M22: Gab | N22: offensive | O22: Arab, Islam | P22: hatespeech | Q22: Islam | R22: offensive | S22: Islam | T22: =COUNTIF(G22:J22,"*Normal*") -> 0 | U22: =COUNTIF(G22:J22,"*Offensive*") -> 2 | V22: =COUNTIF(G22:J22,"*Hate Speech*") -> 2 | W22: =SUM(T22:V22)/4 -> 1 | X22: =IF(T22>2,"Normal", IF(U22>2, "Offensive", IF(V22>2, "Hate Speech"))) -> FALSE | Y22: =STDEV(T22:V22) -> 1.1547005
A23: 022 | B23: 12787888_gab | C23: it a proven medical fact that retards do not know how to use punctuation in a sentence it also a fact that only a homo can tolerate homos do you pitch or catch or both | D23: Homosexual, Disabled | E23: People with disabilities, Gay people | F23: Gay people, People with disabilities | G23: Offensive | H23: Offensive | I23: Offensive | J23: Hate Speech | K23: GM#5 | L23: GM#3 | M23: Gab | N23: offensive | O23: Homosexual, Men, Other | P23: offensive | Q23: Homosexual | R23: hatespeech | S23: Homosexual, Other | T23: =COUNTIF(G23:J23,"*Normal*") -> 0 | U23: =COUNTIF(G23:J23,"*Offensive*") -> 3 | V23: =COUNTIF(G23:J23,"*Hate Speech*") -> 1 | W23: =SUM(T23:V23)/4 -> 1 | X23: =IF(T23>2,"Normal", IF(U23>2, "Offensive", IF(V23>2, "Hate Speech"))) -> Offensive | Y23: =STDEV(T23:V23) -> 1.5275252
A24: 023 | B24: 2901472_gab | C24: <user> he should resign and then commit hara kiri in front of those bloody thirsty muslim scumbag camel jockeys | D24: Muslim | E24: Muslim, Arab | F24: Muslims | G24: Offensive | H24: Hate Speech | I24: Hate Speech | J24: Hate Speech | K24: GM#5 | L24: GM#1 | M24: Gab | N24: hatespeech | O24: Arab, Islam, Men, Women | P24: hatespeech | Q24: Islam | R24: hatespeech | S24: Islam | T24: =COUNTIF(G24:J24,"*Normal*") -> 0 | U24: =COUNTIF(G24:J24,"*Offensive*") -> 1 | V24: =COUNTIF(G24:J24,"*Hate Speech*") -> 3 | W24: =SUM(T24:V24)/4 -> 1 | X24: =IF(T24>2,"Normal", IF(U24>2, "Offensive", IF(V24>2, "Hate Speech"))) -> Hate Speech | Y24: =STDEV(T24:V24) -> 1.5275252
A25: 024 | B25: 1179086548907610113_twitter | C25: <user> i am trynna make it a non gay offensive slur lol i only call non gays faggots you a faggot if you got some bitchassness in you feel me | D25: Homosexual | E25: LGBTQ+ | F25: Gay people | G25: Offensive | H25: Normal | I25: Offensive | J25: Offensive | K25: GM#5 | L25: GM#2 | M25: Twitter | N25: offensive | O25: Homosexual | P25: offensive | Q25: Homosexual | R25: hatespeech | S25: Homosexual | T25: =COUNTIF(G25:J25,"*Normal*") -> 1 | U25: =COUNTIF(G25:J25,"*Offensive*") -> 3 | V25: =COUNTIF(G25:J25,"*Hate Speech*") -> 0 | W25: =SUM(T25:V25)/4 -> 1 | X25: =IF(T25>2,"Normal", IF(U25>2, "Offensive", IF(V25>2, "Hate Speech"))) -> Offensive | Y25: =STDEV(T25:V25) -> 1.5275252
A26: 025 | B26: 14879780_gab | C26: attacking the retard left is lame any way they block you for saying nices things to them | D26: Liberal, Disability | E26: Disability | F26: People with disabilities | G26: Normal | H26: Offensive | I26: Offensive | J26: Offensive | K26: GM#5 | L26: GM#4 | M26: Gab | N26: offensive | O26: Men, Women, Other | P26: offensive | Q26: None | R26: offensive | S26: None | T26: =COUNTIF(G26:J26,"*Normal*") -> 1 | U26: =COUNTIF(G26:J26,"*Offensive*") -> 3 | V26: =COUNTIF(G26:J26,"*Hate Speech*") -> 0 | W26: =SUM(T26:V26)/4 -> 1 | X26: =IF(T26>2,"Normal", IF(U26>2, "Offensive", IF(V26>2, "Hate Speech"))) -> Offensive | Y26: =STDEV(T26:V26) -> 1.5275252
A27: 026 | B27: 1164945865603211264_twitter | C27: i ain ’ t even gone speak on it just know niggas ain ’ t who they claim to be on this social media shit | D27: None | E27: - | F27: Black people | G27: Normal | H27: Normal | I27: Offensive | J27: Offensive | K27: GM#5 | L27: GM#3 | M27: Twitter | N27: offensive | O27: African | P27: normal | Q27: Men, Women | R27: offensive | S27: African | T27: =COUNTIF(G27:J27,"*Normal*") -> 2 | U27: =COUNTIF(G27:J27,"*Offensive*") -> 2 | V27: =COUNTIF(G27:J27,"*Hate Speech*") -> 0 | W27: =SUM(T27:V27)/4 -> 1 | X27: =IF(T27>2,"Normal", IF(U27>2, "Offensive", IF(V27>2, "Hate Speech"))) -> FALSE | Y27: =STDEV(T27:V27) -> 1.1547005
A28: 027 | B28: 24683696_gab | C28: lil fag is also a wannabe sand nigger | D28: Homosexual, Arab | E28: Homosexual, Arab, Muslim | F28: Middle Eastern people | G28: Offensive | H28: Offensive | I28: Hate Speech | J28: Hate Speech | K28: GM#5 | L28: GM#1 | M28: Gab | N28: hatespeech | O28: Arab, Homosexual | P28: hatespeech | Q28: African, Homosexual | R28: hatespeech | S28: Arab, Homosexual | T28: =COUNTIF(G28:J28,"*Normal*") -> 0 | U28: =COUNTIF(G28:J28,"*Offensive*") -> 2 | V28: =COUNTIF(G28:J28,"*Hate Speech*") -> 2 | W28: =SUM(T28:V28)/4 -> 1 | X28: =IF(T28>2,"Normal", IF(U28>2, "Offensive", IF(V28>2, "Hate Speech"))) -> FALSE | Y28: =STDEV(T28:V28) -> 1.1547005
A29: 028 | B29: 1178935990074974208_twitter | C29: like literally what the actual fuck i am so mad at this this meme is stupid having nazi and shit but literally says trans fucking niggers this already giving me blackface vibes like this is crossing the line between being a black person | D29: Transgender, Black | E29: Black People | F29: N/A | G29: Normal | H29: Offensive | I29: Hate Speech | J29: Normal | K29: GM#5 | L29: GM#2 | M29: Twitter | N29: normal | O29: None | P29: normal | Q29: African, Homosexual | R29: normal | S29: None | T29: =COUNTIF(G29:J29,"*Normal*") -> 2 | U29: =COUNTIF(G29:J29,"*Offensive*") -> 1 | V29: =COUNTIF(G29:J29,"*Hate Speech*") -> 1 | W29: =SUM(T29:V29)/4 -> 1 | X29: =IF(T29>2,"Normal", IF(U29>2, "Offensive", IF(V29>2, "Hate Speech"))) -> FALSE | Y29: =STDEV(T29:V29) -> 0.57735027
A30: 029 | B30: 1178755558544936966_twitter | C30: <user> <user> she could not be president of the rag head club | D30: Muslim | E30: Arab, Muslim | F30: Muslims | G30: Offensive | H30: Offensive | I30: Hate Speech | J30: Hate Speech | K30: GM#5 | L30: GM#4 | M30: Twitter | N30: offensive | O30: Arab | P30: hatespeech | Q30: Arab | R30: offensive | S30: Hindu | T30: =COUNTIF(G30:J30,"*Normal*") -> 0 | U30: =COUNTIF(G30:J30,"*Offensive*") -> 2 | V30: =COUNTIF(G30:J30,"*Hate Speech*") -> 2 | W30: =SUM(T30:V30)/4 -> 1 | X30: =IF(T30>2,"Normal", IF(U30>2, "Offensive", IF(V30>2, "Hate Speech"))) -> FALSE | Y30: =STDEV(T30:V30) -> 1.1547005
A31: 030 | B31: 9839066_gab | C31: when the muzzies get their sorry shit together and bomb israel i will not feel sorry or shed a tear i will only lament the loss of christian sites and christian lives | D31: Muslim | E31: Muslim people | F31: Muslims, Jewish people | G31: Normal | H31: Offensive | I31: Hate Speech | J31: Hate Speech | K31: GM#5 | L31: GM#3 | M31: Gab | N31: hatespeech | O31: Arab | P31: hatespeech | Q31: Islam | R31: hatespeech | S31: Islam | T31: =COUNTIF(G31:J31,"*Normal*") -> 1 | U31: =COUNTIF(G31:J31,"*Offensive*") -> 1 | V31: =COUNTIF(G31:J31,"*Hate Speech*") -> 2 | W31: =SUM(T31:V31)/4 -> 1 | X31: =IF(T31>2,"Normal", IF(U31>2, "Offensive", IF(V31>2, "Hate Speech"))) -> FALSE | Y31: =STDEV(T31:V31) -> 0.57735027
A32: 031 | B32: 11216949_gab | C32: for my part like jake blues i hate illinois nazis that nice i hate boomer faggots who think it hip to be down with the neegroes the blues man the blues so cool totally not the music of geriatric nigger loving cuck traitors they had sunglasses | D32: Homosexual, African | E32: AfricanBlack, Pro-nazi/nazi | F32: Jewish people, Gay people | G32: Offensive | I32: Hate Speech | J32: Hate Speech | K32: GM#5 | L32: GM#1 | M32: Gab | N32: offensive | O32: Homosexual, African | P32: hatespeech | Q32: Homosexual, African | R32: hatespeech | S32: Homosexual, African | T32: =COUNTIF(G32:J32,"*Normal*") -> 0 | U32: =COUNTIF(G32:J32,"*Offensive*") -> 1 | V32: =COUNTIF(G32:J32,"*Hate Speech*") -> 2 | W32: =SUM(T32:V32)/4 -> 0.75 | X32: =IF(T32>2,"Normal", IF(U32>2, "Offensive", IF(V32>2, "Hate Speech"))) -> FALSE | Y32: =STDEV(T32:V32) -> 1
A33: 032 | B33: 15068033_gab | C33: do not you love when nazi wannabes complain about israel because hey like we do not want them here but we do not want them there either stupidity | D33: Pro-nazi/nazi | E33: Jewish People | F33: N/A | G33: Normal | H33: Normal | I33: Hate Speech | J33: Normal | K33: GM#5 | L33: GM#2 | M33: Gab | N33: offensive | O33: Jewish | P33: normal | Q33: Islam | R33: normal | S33: Men, Women | T33: =COUNTIF(G33:J33,"*Normal*") -> 3 | U33: =COUNTIF(G33:J33,"*Offensive*") -> 0 | V33: =COUNTIF(G33:J33,"*Hate Speech*") -> 1 | W33: =SUM(T33:V33)/4 -> 1 | X33: =IF(T33>2,"Normal", IF(U33>2, "Offensive", IF(V33>2, "Hate Speech"))) -> Normal | Y33: =STDEV(T33:V33) -> 1.5275252
A34: 033 | B34: 1220545521682731008_twitter | C34: <user> <user> remember when you collaborated with neo nazis on a seth rich conspiracy documentary | D34: None | E34: Jewish, Pro-nazi/nazi | F34: N/A | G34: Normal | H34: Normal | I34: Hate Speech | J34: Normal | K34: GM#5 | L34: GM#4 | M34: Twitter | N34: normal | O34: None | P34: normal | Q34: Other | R34: offensive | S34: Other | T34: =COUNTIF(G34:J34,"*Normal*") -> 3 | U34: =COUNTIF(G34:J34,"*Offensive*") -> 0 | V34: =COUNTIF(G34:J34,"*Hate Speech*") -> 1 | W34: =SUM(T34:V34)/4 -> 1 | X34: =IF(T34>2,"Normal", IF(U34>2, "Offensive", IF(V34>2, "Hate Speech"))) -> Normal | Y34: =STDEV(T34:V34) -> 1.5275252
A35: 034 | B35: 1116946053478125571_twitter | C35: then hoes stole my choreo and still managed to make it look bad and lose with it lmfao | D35: Woman | E35: Women | F35: Women | G35: Normal | H35: Normal | I35: Offensive | J35: Offensive | K35: GM#5 | L35: GM#3 | M35: Twitter | N35: offensive | O35: Women | P35: offensive | Q35: Women | R35: offensive | S35: Women | T35: =COUNTIF(G35:J35,"*Normal*") -> 2 | U35: =COUNTIF(G35:J35,"*Offensive*") -> 2 | V35: =COUNTIF(G35:J35,"*Hate Speech*") -> 0 | W35: =SUM(T35:V35)/4 -> 1 | X35: =IF(T35>2,"Normal", IF(U35>2, "Offensive", IF(V35>2, "Hate Speech"))) -> FALSE | Y35: =STDEV(T35:V35) -> 1.1547005
A36: 035 | B36: 19506620_gab | C36: fbi cover up smells of another muzrat terrorist attack | D36: Muslim | E36: Muslim | F36: Muslims | G36: Normal | H36: Offensive | I36: Hate Speech | J36: Hate Speech | K36: GM#5 | L36: GM#1 | M36: Gab | N36: hatespeech | O36: Islam | P36: hatespeech | Q36: Islam | R36: hatespeech | S36: Islam | T36: =COUNTIF(G36:J36,"*Normal*") -> 1 | U36: =COUNTIF(G36:J36,"*Offensive*") -> 1 | V36: =COUNTIF(G36:J36,"*Hate Speech*") -> 2 | W36: =SUM(T36:V36)/4 -> 1 | X36: =IF(T36>2,"Normal", IF(U36>2, "Offensive", IF(V36>2, "Hate Speech"))) -> FALSE | Y36: =STDEV(T36:V36) -> 0.57735027
A37: 036 | B37: 1179035441854443520_twitter | C37: white devils like it i am drinking coffee brought to me by white devils sidekicks | D37: Causasian | E37: White People | F37: White people | G37: Normal | H37: Normal | I37: Hate Speech | J37: Offensive | K37: GM#5 | L37: GM#2 | M37: Twitter | N37: hatespeech | O37: Caucasian | P37: normal | Q37: None | R37: hatespeech | S37: Caucasian | T37: =COUNTIF(G37:J37,"*Normal*") -> 2 | U37: =COUNTIF(G37:J37,"*Offensive*") -> 1 | V37: =COUNTIF(G37:J37,"*Hate Speech*") -> 1 | W37: =SUM(T37:V37)/4 -> 1 | X37: =IF(T37>2,"Normal", IF(U37>2, "Offensive", IF(V37>2, "Hate Speech"))) -> FALSE | Y37: =STDEV(T37:V37) -> 0.57735027
A38: 037 | B38: 1211743854401064961_twitter | C38: i didn ’ t get a pedicure last rome i got my nails done n now my feet look brazy this is ghetto | D38: African | E38: AfricanBlack | F38: N/A | G38: Normal | H38: Offensive | I38: Offensive | J38: Normal | K38: GM#5 | L38: GM#4 | M38: Twitter | N38: offensive | O38: Other | P38: offensive | Q38: None | R38: normal | S38: Other | T38: =COUNTIF(G38:J38,"*Normal*") -> 2 | U38: =COUNTIF(G38:J38,"*Offensive*") -> 2 | V38: =COUNTIF(G38:J38,"*Hate Speech*") -> 0 | W38: =SUM(T38:V38)/4 -> 1 | X38: =IF(T38>2,"Normal", IF(U38>2, "Offensive", IF(V38>2, "Hate Speech"))) -> FALSE | Y38: =STDEV(T38:V38) -> 1.1547005
A39: 038 | B39: 13567394_gab | C39: this coons constituents voted for her just to get her out of their district they were embarrassed by her so they took out the trash | D39: None | E39: Black people | F39: Black people | G39: Offensive | H39: Normal | I39: Hate Speech | J39: Hate Speech | K39: GM#5 | L39: GM#3 | M39: Gab | N39: hatespeech | O39: African, Women | P39: offensive | Q39: African | R39: hatespeech | S39: African | T39: =COUNTIF(G39:J39,"*Normal*") -> 1 | U39: =COUNTIF(G39:J39,"*Offensive*") -> 1 | V39: =COUNTIF(G39:J39,"*Hate Speech*") -> 2 | W39: =SUM(T39:V39)/4 -> 1 | X39: =IF(T39>2,"Normal", IF(U39>2, "Offensive", IF(V39>2, "Hate Speech"))) -> FALSE | Y39: =STDEV(T39:V39) -> 0.57735027
A40: 039 | B40: 26510414_gab | C40: i think we are past the negotiation phase it time to issue an ultimatum all sand niggers and kikes out of america or get executed an invader | D40: Arab, Jewish | E40: AfricanBlack, Arab, Muslim, Jewish | F40: Middle Eastern people, Jewish people | G40: Hate Speech | H40: Hate Speech | I40: Hate Speech | J40: Hate Speech | K40: GM#5 | L40: GM#1 | M40: Gab | N40: hatespeech | O40: Arab, Jewish, Refugee | P40: hatespeech | Q40: Arab, Islam | R40: hatespeech | S40: Arab, Jewish | T40: =COUNTIF(G40:J40,"*Normal*") -> 0 | U40: =COUNTIF(G40:J40,"*Offensive*") -> 0 | V40: =COUNTIF(G40:J40,"*Hate Speech*") -> 4 | W40: =SUM(T40:V40)/4 -> 1 | X40: =IF(T40>2,"Normal", IF(U40>2, "Offensive", IF(V40>2, "Hate Speech"))) -> Hate Speech | Y40: =STDEV(T40:V40) -> 2.3094011
...

Sheet Feuille 2
A1: Old Target Group Labels: | B1: New Target Group Labels: | C1: COUNT:
A2: African | B2: African | C2: =COUNTIF('Feuille 1'!D2:D501,"*African*") -> 33
A3: Black | B3: Black | C3: =COUNTIF('Feuille 1'!D2:D501,"*Black*") -> 57
A4: Chinese | B4: Chinese | C4: =COUNTIF('Feuille 1'!D2:D501,"*Chinese*") -> 4
A5: Asians | B5: Asian | C5: =COUNTIF('Feuille 1'!D2:D501,"*Asian*") -> 16
A6: Brown | B6: Brown | C6: =COUNTIF('Feuille 1'!D2:D501,"*Brown*") -> 2
A7: Arab | B7: Arab | C7: =COUNTIF('Feuille 1'!D2:D501,"*Arab*") -> 11
A8: Caucasians | B8: Caucasian | C8: =COUNTIF('Feuille 1'!D2:D501,"*Caucasian*") -> 9
A9: White
A10: Jewish | B10: Jewish | C10: =COUNTIF('Feuille 1'!D2:D501,"*Jewish*") -> 34
A11: Mexican | B11: Mexican | C11: =COUNTIF('Feuille 1'!D2:D501,"*Mexican*") -> 1
A12: Hispanics | B12: Hispanic | C12: =COUNTIF('Feuille 1'!D2:D501,"*Hispanic*") -> 2
A13: Latino | B13: Latino | C13: =COUNTIF('Feuille 1'!D2:D501,"*Latin*") -> 4
A14: Native Americans | B14: Native American | C14: =COUNTIF('Feuille 1'!D2:D501,"*Native American*") -> 1
A15: Australians | B15: Australian | C15: =COUNTIF('Feuille 1'!D2:D501,"*Australian*") -> 1
A16: Indians | B16: Indian | C16: =COUNTIF('Feuille 1'!D2:D501,"*Indian*") -> 1
A17: Somali | B17: Somali | C17: =COUNTIF('Feuille 1'!D2:D501,"*Somali*") -> 1
A18: Biracial | B18: Biracial | C18: =COUNTIF('Feuille 1'!D2:D501,"*Biracial*") -> 1
A19: Muslims | B19: Muslim | C19: =COUNTIF('Feuille 1'!D2:D501,"*Muslim*") -> 57
A20: Islam
A21: Homosexual | B21: Homosexual | C21: =COUNTIF('Feuille 1'!D2:D501,"*Homosexual*") -> 62
A22: Trans | B22: Trans | C22: =COUNTIF('Feuille 1'!D2:D501,"*Trans*") -> 3
A23: Queer | B23: Queer | C23: =COUNTIF('Feuille 1'!D2:D501,"*Queer*") -> 4
A24: Liberals | B24: Liberal | C24: =COUNTIF('Feuille 1'!D2:D501,"*Liberal*") -> 7
A25: Communists | B25: Communist | C25: =COUNTIF('Feuille 1'!D2:D501,"*Communist*") -> 1
A26: Right-wing | B26: Right-wing | C26: =COUNTIF('Feuille 1'!D2:D501,"*Right-wing*") -> 1
A27: Democrats | B27: Democrat | C27: =COUNTIF('Feuille 1'!D2:D501,"*Democrat*") -> 1
A28: Pro-nazi/nazi | B28: Pro-nazi/nazi | C28: =COUNTIF('Feuille 1'!D2:D501,"*Pro-nazi/nazi*") -> 3
A29: Disability | B29: Disability | C29: =COUNTIF('Feuille 1'!D2:D501,"*Disability*") -> 4
A30: Rich | B30: Economic Status | C30: =COUNTIF('Feuille 1'!D2:D501,"*Economic Status*") -> 8
A31: Working Class
A32: Economic
A33: Men | B33: Men | C33: =COUNTIF('Feuille 1'!D2:D501,"*Men*") -> 3
A34: Women | B34: Woman | C34: =COUNTIF('Feuille 1'!D2:D501,"*Woman*") -> 59
A35: Victims of SA | B35: Victims of SA | C35: =COUNTIF('Feuille 1'!D2:D501,"*Victims of SA*") -> 1
A36: Immigrants | B36: Immigrant | C36: =COUNTIF('Feuille 1'!D2:D501,"*Immigrant*") -> 18
A37: Refugees | B37: Refugee | C37: =COUNTIF('Feuille 1'!D2:D501,"*Refugee*") -> 6
A38: Protestors | B38: Protestor | C38: =COUNTIF('Feuille 1'!D2:D501,"*Protestor*") -> 1
A39: Journalists | B39: Journalist | C39: =COUNTIF('Feuille 1'!D2:D501,"*Journalist*") -> 2
A40: Uneducated | B40: Education | C40: =COUNTIF('Feuille 1'!D2:D501,"*Education*") -> 1
...

Sheet Findings
A1: Annotation Convergence Analysis | Decoding Biases in AI
A2: Comparing Grok, Claude, and five human annotators (H1, H2, SA1, SA2, SA3) | N = 500 posts
A4: 1 | Classification Distribution by Annotator
A5: Annotator | B5: Normal | C5: Offensive | D5: Hate Speech | E5: Total Valid
A6: Grok | B6: 62 (12.4%) | C6: 201 (40.2%) | D6: 237 (47.4%) | E6: 500
A7: Claude | B7: 213 (42.6%) | C7: 114 (22.8%) | D7: 173 (34.6%) | E7: 500 | I7: CLAUDE | L7: TOTAL
A8: H1 | B8: 201 (41.3%) | C8: 250 (51.3%) | D8: 36 (7.4%) | E8: 487 | I8: NORMAL | J8: OFFENSIVE | K8: HATE SPEECH
A9: H2 | B9: 196 (39.8%) | C9: 253 (51.4%) | D9: 43 (8.7%) | E9: 492 | G9: GROK | H9: NORMAL | I9: 61 | J9: 1 | K9: 0 | L9: 62
A10: SA1 | B10: 188 (37.6%) | C10: 176 (35.2%) | D10: 136 (27.2%) | E10: 500 | H10: OFFENSIVE | I10: 90 | J10: 95 | K10: 16 | L10: 201
A11: SA2 | B11: 193 (38.6%) | C11: 161 (32.2%) | D11: 146 (29.2%) | E11: 500 | H11: HATE SPEECH | I11: 62 | J11: 18 | K11: 157 | L11: 237
A12: SA3 | B12: 179 (35.8%) | C12: 166 (33.2%) | D12: 155 (31.0%) | E12: 500 | G12: TOTAL | I12: 213 | J12: 114 | K12: 173 | L12: 500
A16: Cross-tabulation: Grok vs Claude (absolute counts) | G16: Metric | H16: Count | I16: % of valid n
A17: Grok \ Claude → | B17: Hate Speech | C17: Offensive | D17: Normal | E17: Row Total | G17: Overall Agreement (exact match) | H17: 313 | I17: 62.6%
A18: Hate Speech | B18: 157 | C18: 18 | D18: 62 | E18: 237 | G18: Hate Speech agreement | H18: 157 | I18: 66.2%
A19: Offensive | B19: 16 | C19: 95 | D19: 90 | E19: 201 | G19: Offensive agreement | H19: 95 | I19: 47.3%
A20: Normal | B20: 0 | C20: 1 | D20: 61 | E20: 62 | G20: Normal agreement | H20: 61 | I20: 98.4%
A21: Column Total | B21: 173 | C21: 114 | D21: 213 | E21: 500 | G21: Overall Disagreement | H21: 187 | I21: 37.4%
A23: Cross-tabulation: Grok vs Group Consensus (H1+H2 only) | G23: Metric | H23: Count | I23: % of valid n
A24: Grok \ Human → | B24: Hate Speech | C24: Offensive | D24: Normal | E24: Row Total | G24: Overall Agreement (exact match) | H24: 134 | I24: 38.4%
A25: Hate Speech | B25: 16 | C25: 113 | D25: 24 | E25: 153 | G25: Hate Speech agreement | H25: 16 | I25: 10.5%
A26: Offensive | B26: 2 | C26: 70 | D26: 73 | E26: 145 | G26: Offensive agreement | H26: 70 | I26: 48.3%
A27: Offensive | B27: 2 | C27: 1 | D27: 48 | E27: 51 | G27: Normal agreement | H27: 48 | I27: 94.1%
A28: Column Total | B28: 20 | C28: 184 | D28: 145 | E28: 349 | G28: Overall Disagreement | H28: 215 | I28: 61.6%
A30: Cross-tabulation: Claude vs Group Consensus (H1+H2 only) | G30: Metric | H30: Count | I30: % of valid n
A31: Claude \ Human → | B31: Hate Speech | C31: Offensive | D31: Normal | E31: Row Total | G31: Overall Agreement (exact match) | H31: 188 | I31: 53.9%
A32: Hate Speech | B32: 14 | C32: 97 | D32: 9 | E32: 120 | G32: Hate Speech agreement | H32: 14 | I32: 11.7%
A33: Offensive | B33: 5 | C33: 55 | D33: 17 | E33: 77 | G33: Offensive agreement | H33: 55 | I33: 71.4%
A34: Normal | B34: 1 | C34: 32 | D34: 119 | E34: 152 | G34: Normal agreement | H34: 119 | I34: 78.3%
A35: Column Total | B35: 20 | C35: 184 | D35: 145 | E35: 349 | G35: Overall Disagreement | H35: 161 | I35: 46.1%
I38: HUMAN CONSENUS | L38: TOTAL
I39: NORMAL | J39: OFFENSIVE | K39: HATE SPEECH
G40: GROK | H40: NORMAL | I40: 48 | J40: 1 | K40: 2 | L40: 51
H41: OFFENSIVE | I41: 73 | J41: 70 | K41: 2 | L41: 145
H42: HATE SPEECH | I42: 24 | J42: 113 | K42: 16 | L42: 153
G43: TOTAL | I43: 145 | J43: 184 | K43: 20 | L43: 349
I45: HUMAN CONSENUS | L45: TOTAL
I46: NORMAL | J46: OFFENSIVE | K46: HATE SPEECH
G47: CLAUDE | H47: NORMAL | I47: 119 | J47: 32 | K47: 1 | L47: 152
H48: OFFENSIVE | I48: 17 | J48: 55 | K48: 5 | L48: 77
H49: HATE SPEECH | I49: 9 | J49: 97 | K49: 14 | L49: 120
...

Sheet Feuille 4
